[2023-10-22T16:56:58.119+0000] {taskinstance.py:1159} INFO - Dependencies all met for dep_context=non-requeueable deps ti=<TaskInstance: update_dwh.stg_update manual__2023-10-22T16:56:56.885745+00:00 [queued]>
[2023-10-22T16:56:58.126+0000] {taskinstance.py:1159} INFO - Dependencies all met for dep_context=requeueable deps ti=<TaskInstance: update_dwh.stg_update manual__2023-10-22T16:56:56.885745+00:00 [queued]>
[2023-10-22T16:56:58.127+0000] {taskinstance.py:1361} INFO - Starting attempt 1 of 1
[2023-10-22T16:56:58.134+0000] {taskinstance.py:1382} INFO - Executing <Task(PythonOperator): stg_update> on 2023-10-22 16:56:56.885745+00:00
[2023-10-22T16:56:58.138+0000] {standard_task_runner.py:57} INFO - Started process 713 to run task
[2023-10-22T16:56:58.139+0000] {standard_task_runner.py:84} INFO - Running: ['***', 'tasks', 'run', 'update_dwh', 'stg_update', 'manual__2023-10-22T16:56:56.885745+00:00', '--job-id', '190', '--raw', '--subdir', 'DAGS_FOLDER/update_dwh_dag.py', '--cfg-path', '/tmp/tmpfyajjh9j']
[2023-10-22T16:56:58.140+0000] {standard_task_runner.py:85} INFO - Job 190: Subtask stg_update
[2023-10-22T16:56:58.168+0000] {task_command.py:416} INFO - Running <TaskInstance: update_dwh.stg_update manual__2023-10-22T16:56:56.885745+00:00 [running]> on host 1f8bb8a692af
[2023-10-22T16:56:58.210+0000] {taskinstance.py:1662} INFO - Exporting env vars: AIRFLOW_CTX_DAG_OWNER='***' AIRFLOW_CTX_DAG_ID='update_dwh' AIRFLOW_CTX_TASK_ID='stg_update' AIRFLOW_CTX_EXECUTION_DATE='2023-10-22T16:56:56.885745+00:00' AIRFLOW_CTX_TRY_NUMBER='1' AIRFLOW_CTX_DAG_RUN_ID='manual__2023-10-22T16:56:56.885745+00:00'
[2023-10-22T16:56:58.227+0000] {base.py:73} INFO - Using connection ID 'stg_conn' for task execution.
[2023-10-22T16:56:58.231+0000] {base.py:73} INFO - Using connection ID 'stg_conn' for task execution.
[2023-10-22T16:56:58.337+0000] {taskinstance.py:1937} ERROR - Task failed with exception
Traceback (most recent call last):
  File "/home/airflow/.local/lib/python3.8/site-packages/airflow/operators/python.py", line 192, in execute
    return_value = self.execute_callable()
  File "/home/airflow/.local/lib/python3.8/site-packages/airflow/operators/python.py", line 209, in execute_callable
    return self.python_callable(*self.op_args, **self.op_kwargs)
  File "/opt/airflow/dags/update_dwh_dag.py", line 26, in _stg_update
    truncate_table(
  File "/opt/airflow/dags/utils/pg_utils.py", line 9, in truncate_table
    cur.execute(query)
psycopg2.errors.InsufficientPrivilege: permission denied for table stg_table

[2023-10-22T16:56:58.349+0000] {taskinstance.py:1400} INFO - Marking task as FAILED. dag_id=update_dwh, task_id=stg_update, execution_date=20231022T165656, start_date=20231022T165658, end_date=20231022T165658
[2023-10-22T16:56:58.363+0000] {standard_task_runner.py:104} ERROR - Failed to execute job 190 for task stg_update (permission denied for table stg_table
; 713)
[2023-10-22T16:56:58.392+0000] {local_task_job_runner.py:228} INFO - Task exited with return code 1
[2023-10-22T16:56:58.411+0000] {taskinstance.py:2778} INFO - 0 downstream tasks scheduled from follow-on schedule check
