[2023-10-22T16:56:30.715+0000] {taskinstance.py:1159} INFO - Dependencies all met for dep_context=non-requeueable deps ti=<TaskInstance: update_dwh.stg_update manual__2023-10-22T16:56:29.119825+00:00 [queued]>
[2023-10-22T16:56:30.720+0000] {taskinstance.py:1159} INFO - Dependencies all met for dep_context=requeueable deps ti=<TaskInstance: update_dwh.stg_update manual__2023-10-22T16:56:29.119825+00:00 [queued]>
[2023-10-22T16:56:30.721+0000] {taskinstance.py:1361} INFO - Starting attempt 1 of 1
[2023-10-22T16:56:30.729+0000] {taskinstance.py:1382} INFO - Executing <Task(PythonOperator): stg_update> on 2023-10-22 16:56:29.119825+00:00
[2023-10-22T16:56:30.733+0000] {standard_task_runner.py:57} INFO - Started process 702 to run task
[2023-10-22T16:56:30.735+0000] {standard_task_runner.py:84} INFO - Running: ['***', 'tasks', 'run', 'update_dwh', 'stg_update', 'manual__2023-10-22T16:56:29.119825+00:00', '--job-id', '189', '--raw', '--subdir', 'DAGS_FOLDER/update_dwh_dag.py', '--cfg-path', '/tmp/tmpfyk84rt0']
[2023-10-22T16:56:30.736+0000] {standard_task_runner.py:85} INFO - Job 189: Subtask stg_update
[2023-10-22T16:56:30.766+0000] {task_command.py:416} INFO - Running <TaskInstance: update_dwh.stg_update manual__2023-10-22T16:56:29.119825+00:00 [running]> on host 1f8bb8a692af
[2023-10-22T16:56:30.815+0000] {taskinstance.py:1662} INFO - Exporting env vars: AIRFLOW_CTX_DAG_OWNER='***' AIRFLOW_CTX_DAG_ID='update_dwh' AIRFLOW_CTX_TASK_ID='stg_update' AIRFLOW_CTX_EXECUTION_DATE='2023-10-22T16:56:29.119825+00:00' AIRFLOW_CTX_TRY_NUMBER='1' AIRFLOW_CTX_DAG_RUN_ID='manual__2023-10-22T16:56:29.119825+00:00'
[2023-10-22T16:56:30.833+0000] {base.py:73} INFO - Using connection ID 'stg_conn' for task execution.
[2023-10-22T16:56:30.838+0000] {base.py:73} INFO - Using connection ID 'stg_conn' for task execution.
[2023-10-22T16:56:30.948+0000] {taskinstance.py:1937} ERROR - Task failed with exception
Traceback (most recent call last):
  File "/home/airflow/.local/lib/python3.8/site-packages/airflow/operators/python.py", line 192, in execute
    return_value = self.execute_callable()
  File "/home/airflow/.local/lib/python3.8/site-packages/airflow/operators/python.py", line 209, in execute_callable
    return self.python_callable(*self.op_args, **self.op_kwargs)
  File "/opt/airflow/dags/update_dwh_dag.py", line 26, in _stg_update
    truncate_table(
  File "/opt/airflow/dags/utils/pg_utils.py", line 9, in truncate_table
    cur.execute(query)
psycopg2.errors.UndefinedTable: relation "staging.stg_data" does not exist

[2023-10-22T16:56:30.955+0000] {taskinstance.py:1400} INFO - Marking task as FAILED. dag_id=update_dwh, task_id=stg_update, execution_date=20231022T165629, start_date=20231022T165630, end_date=20231022T165630
[2023-10-22T16:56:30.964+0000] {standard_task_runner.py:104} ERROR - Failed to execute job 189 for task stg_update (relation "staging.stg_data" does not exist
; 702)
[2023-10-22T16:56:30.987+0000] {local_task_job_runner.py:228} INFO - Task exited with return code 1
[2023-10-22T16:56:30.999+0000] {taskinstance.py:2778} INFO - 0 downstream tasks scheduled from follow-on schedule check
