[2023-10-22T16:41:15.757+0000] {taskinstance.py:1159} INFO - Dependencies all met for dep_context=non-requeueable deps ti=<TaskInstance: update_dwh.stg_update scheduled__2016-04-10T00:00:00+00:00 [queued]>
[2023-10-22T16:41:15.763+0000] {taskinstance.py:1159} INFO - Dependencies all met for dep_context=requeueable deps ti=<TaskInstance: update_dwh.stg_update scheduled__2016-04-10T00:00:00+00:00 [queued]>
[2023-10-22T16:41:15.763+0000] {taskinstance.py:1361} INFO - Starting attempt 1 of 1
[2023-10-22T16:41:15.774+0000] {taskinstance.py:1382} INFO - Executing <Task(PythonOperator): stg_update> on 2016-04-10 00:00:00+00:00
[2023-10-22T16:41:15.779+0000] {standard_task_runner.py:57} INFO - Started process 423 to run task
[2023-10-22T16:41:15.781+0000] {standard_task_runner.py:84} INFO - Running: ['***', 'tasks', 'run', 'update_dwh', 'stg_update', 'scheduled__2016-04-10T00:00:00+00:00', '--job-id', '178', '--raw', '--subdir', 'DAGS_FOLDER/update_dwh_dag.py', '--cfg-path', '/tmp/tmpp6nxshjp']
[2023-10-22T16:41:15.782+0000] {standard_task_runner.py:85} INFO - Job 178: Subtask stg_update
[2023-10-22T16:41:15.813+0000] {task_command.py:416} INFO - Running <TaskInstance: update_dwh.stg_update scheduled__2016-04-10T00:00:00+00:00 [running]> on host 1f8bb8a692af
[2023-10-22T16:41:15.864+0000] {taskinstance.py:1662} INFO - Exporting env vars: AIRFLOW_CTX_DAG_OWNER='***' AIRFLOW_CTX_DAG_ID='update_dwh' AIRFLOW_CTX_TASK_ID='stg_update' AIRFLOW_CTX_EXECUTION_DATE='2016-04-10T00:00:00+00:00' AIRFLOW_CTX_TRY_NUMBER='1' AIRFLOW_CTX_DAG_RUN_ID='scheduled__2016-04-10T00:00:00+00:00'
[2023-10-22T16:41:15.867+0000] {taskinstance.py:1937} ERROR - Task failed with exception
Traceback (most recent call last):
  File "/home/airflow/.local/lib/python3.8/site-packages/airflow/operators/python.py", line 192, in execute
    return_value = self.execute_callable()
  File "/home/airflow/.local/lib/python3.8/site-packages/airflow/operators/python.py", line 209, in execute_callable
    return self.python_callable(*self.op_args, **self.op_kwargs)
  File "/opt/airflow/dags/update_dwh_dag.py", line 16, in _stg_update
    raw_file = pd.read_csv(SOURCE_FILE)
  File "/home/airflow/.local/lib/python3.8/site-packages/pandas/io/parsers/readers.py", line 912, in read_csv
    return _read(filepath_or_buffer, kwds)
  File "/home/airflow/.local/lib/python3.8/site-packages/pandas/io/parsers/readers.py", line 577, in _read
    parser = TextFileReader(filepath_or_buffer, **kwds)
  File "/home/airflow/.local/lib/python3.8/site-packages/pandas/io/parsers/readers.py", line 1407, in __init__
    self._engine = self._make_engine(f, self.engine)
  File "/home/airflow/.local/lib/python3.8/site-packages/pandas/io/parsers/readers.py", line 1661, in _make_engine
    self.handles = get_handle(
  File "/home/airflow/.local/lib/python3.8/site-packages/pandas/io/common.py", line 859, in get_handle
    handle = open(
FileNotFoundError: [Errno 2] No such file or directory: 'employees.csv'
[2023-10-22T16:41:15.875+0000] {taskinstance.py:1400} INFO - Marking task as FAILED. dag_id=update_dwh, task_id=stg_update, execution_date=20160410T000000, start_date=20231022T164115, end_date=20231022T164115
[2023-10-22T16:41:15.885+0000] {standard_task_runner.py:104} ERROR - Failed to execute job 178 for task stg_update ([Errno 2] No such file or directory: 'employees.csv'; 423)
[2023-10-22T16:41:15.913+0000] {local_task_job_runner.py:228} INFO - Task exited with return code 1
[2023-10-22T16:41:15.925+0000] {taskinstance.py:2778} INFO - 0 downstream tasks scheduled from follow-on schedule check
