[2023-10-22T16:50:04.413+0000] {taskinstance.py:1159} INFO - Dependencies all met for dep_context=non-requeueable deps ti=<TaskInstance: update_dwh.stg_update manual__2023-10-22T16:50:02.514976+00:00 [queued]>
[2023-10-22T16:50:04.418+0000] {taskinstance.py:1159} INFO - Dependencies all met for dep_context=requeueable deps ti=<TaskInstance: update_dwh.stg_update manual__2023-10-22T16:50:02.514976+00:00 [queued]>
[2023-10-22T16:50:04.418+0000] {taskinstance.py:1361} INFO - Starting attempt 1 of 1
[2023-10-22T16:50:04.425+0000] {taskinstance.py:1382} INFO - Executing <Task(PythonOperator): stg_update> on 2023-10-22 16:50:02.514976+00:00
[2023-10-22T16:50:04.429+0000] {standard_task_runner.py:57} INFO - Started process 600 to run task
[2023-10-22T16:50:04.431+0000] {standard_task_runner.py:84} INFO - Running: ['***', 'tasks', 'run', 'update_dwh', 'stg_update', 'manual__2023-10-22T16:50:02.514976+00:00', '--job-id', '187', '--raw', '--subdir', 'DAGS_FOLDER/update_dwh_dag.py', '--cfg-path', '/tmp/tmpvzodrphc']
[2023-10-22T16:50:04.432+0000] {standard_task_runner.py:85} INFO - Job 187: Subtask stg_update
[2023-10-22T16:50:04.460+0000] {task_command.py:416} INFO - Running <TaskInstance: update_dwh.stg_update manual__2023-10-22T16:50:02.514976+00:00 [running]> on host 1f8bb8a692af
[2023-10-22T16:50:04.502+0000] {taskinstance.py:1662} INFO - Exporting env vars: AIRFLOW_CTX_DAG_OWNER='***' AIRFLOW_CTX_DAG_ID='update_dwh' AIRFLOW_CTX_TASK_ID='stg_update' AIRFLOW_CTX_EXECUTION_DATE='2023-10-22T16:50:02.514976+00:00' AIRFLOW_CTX_TRY_NUMBER='1' AIRFLOW_CTX_DAG_RUN_ID='manual__2023-10-22T16:50:02.514976+00:00'
[2023-10-22T16:50:04.515+0000] {taskinstance.py:1937} ERROR - Task failed with exception
Traceback (most recent call last):
  File "/home/airflow/.local/lib/python3.8/site-packages/airflow/operators/python.py", line 192, in execute
    return_value = self.execute_callable()
  File "/home/airflow/.local/lib/python3.8/site-packages/airflow/operators/python.py", line 209, in execute_callable
    return self.python_callable(*self.op_args, **self.op_kwargs)
  File "/opt/airflow/dags/update_dwh_dag.py", line 17, in _stg_update
    raw_file.drop(
  File "/home/airflow/.local/lib/python3.8/site-packages/pandas/core/frame.py", line 5258, in drop
    return super().drop(
  File "/home/airflow/.local/lib/python3.8/site-packages/pandas/core/generic.py", line 4549, in drop
    obj = obj._drop_axis(labels, axis, level=level, errors=errors)
  File "/home/airflow/.local/lib/python3.8/site-packages/pandas/core/generic.py", line 4591, in _drop_axis
    new_axis = axis.drop(labels, errors=errors)
  File "/home/airflow/.local/lib/python3.8/site-packages/pandas/core/indexes/base.py", line 6699, in drop
    raise KeyError(f"{list(labels[mask])} not found in axis")
KeyError: "['EmployeeCount'] not found in axis"
[2023-10-22T16:50:04.523+0000] {taskinstance.py:1400} INFO - Marking task as FAILED. dag_id=update_dwh, task_id=stg_update, execution_date=20231022T165002, start_date=20231022T165004, end_date=20231022T165004
[2023-10-22T16:50:04.531+0000] {standard_task_runner.py:104} ERROR - Failed to execute job 187 for task stg_update ("['EmployeeCount'] not found in axis"; 600)
[2023-10-22T16:50:04.563+0000] {local_task_job_runner.py:228} INFO - Task exited with return code 1
[2023-10-22T16:50:04.584+0000] {taskinstance.py:2778} INFO - 0 downstream tasks scheduled from follow-on schedule check
