[2023-10-22T16:37:11.517+0000] {taskinstance.py:1159} INFO - Dependencies all met for dep_context=non-requeueable deps ti=<TaskInstance: update_dwh.stg_update scheduled__2016-03-10T00:00:00+00:00 [queued]>
[2023-10-22T16:37:11.529+0000] {taskinstance.py:1159} INFO - Dependencies all met for dep_context=requeueable deps ti=<TaskInstance: update_dwh.stg_update scheduled__2016-03-10T00:00:00+00:00 [queued]>
[2023-10-22T16:37:11.530+0000] {taskinstance.py:1361} INFO - Starting attempt 1 of 1
[2023-10-22T16:37:11.547+0000] {taskinstance.py:1382} INFO - Executing <Task(PythonOperator): stg_update> on 2016-03-10 00:00:00+00:00
[2023-10-22T16:37:11.553+0000] {standard_task_runner.py:57} INFO - Started process 276 to run task
[2023-10-22T16:37:11.557+0000] {standard_task_runner.py:84} INFO - Running: ['***', 'tasks', 'run', 'update_dwh', 'stg_update', 'scheduled__2016-03-10T00:00:00+00:00', '--job-id', '147', '--raw', '--subdir', 'DAGS_FOLDER/update_dwh_dag.py', '--cfg-path', '/tmp/tmpulggd2pd']
[2023-10-22T16:37:11.559+0000] {standard_task_runner.py:85} INFO - Job 147: Subtask stg_update
[2023-10-22T16:37:11.617+0000] {task_command.py:416} INFO - Running <TaskInstance: update_dwh.stg_update scheduled__2016-03-10T00:00:00+00:00 [running]> on host 1f8bb8a692af
[2023-10-22T16:37:11.694+0000] {taskinstance.py:1662} INFO - Exporting env vars: AIRFLOW_CTX_DAG_OWNER='***' AIRFLOW_CTX_DAG_ID='update_dwh' AIRFLOW_CTX_TASK_ID='stg_update' AIRFLOW_CTX_EXECUTION_DATE='2016-03-10T00:00:00+00:00' AIRFLOW_CTX_TRY_NUMBER='1' AIRFLOW_CTX_DAG_RUN_ID='scheduled__2016-03-10T00:00:00+00:00'
[2023-10-22T16:37:11.700+0000] {taskinstance.py:1937} ERROR - Task failed with exception
Traceback (most recent call last):
  File "/home/airflow/.local/lib/python3.8/site-packages/airflow/operators/python.py", line 192, in execute
    return_value = self.execute_callable()
  File "/home/airflow/.local/lib/python3.8/site-packages/airflow/operators/python.py", line 209, in execute_callable
    return self.python_callable(*self.op_args, **self.op_kwargs)
  File "/opt/airflow/dags/update_dwh_dag.py", line 18, in _stg_update
    raw_file = pd.read_csv(SOURCE_FILE)
  File "/home/airflow/.local/lib/python3.8/site-packages/pandas/io/parsers/readers.py", line 912, in read_csv
    return _read(filepath_or_buffer, kwds)
  File "/home/airflow/.local/lib/python3.8/site-packages/pandas/io/parsers/readers.py", line 577, in _read
    parser = TextFileReader(filepath_or_buffer, **kwds)
  File "/home/airflow/.local/lib/python3.8/site-packages/pandas/io/parsers/readers.py", line 1407, in __init__
    self._engine = self._make_engine(f, self.engine)
  File "/home/airflow/.local/lib/python3.8/site-packages/pandas/io/parsers/readers.py", line 1661, in _make_engine
    self.handles = get_handle(
  File "/home/airflow/.local/lib/python3.8/site-packages/pandas/io/common.py", line 859, in get_handle
    handle = open(
FileNotFoundError: [Errno 2] No such file or directory: 'employees.csv'
[2023-10-22T16:37:11.716+0000] {taskinstance.py:1400} INFO - Marking task as FAILED. dag_id=update_dwh, task_id=stg_update, execution_date=20160310T000000, start_date=20231022T163711, end_date=20231022T163711
[2023-10-22T16:37:11.732+0000] {standard_task_runner.py:104} ERROR - Failed to execute job 147 for task stg_update ([Errno 2] No such file or directory: 'employees.csv'; 276)
[2023-10-22T16:37:11.741+0000] {local_task_job_runner.py:228} INFO - Task exited with return code 1
[2023-10-22T16:37:11.762+0000] {taskinstance.py:2778} INFO - 0 downstream tasks scheduled from follow-on schedule check
